<mujoco version="1.0">
	<compiler inertiafromgeom="true"/>
	<engine gravity="0 0 -9.81" integrator="RK4" timestep="0.001" regimpulse="0.0001" imperrreduce="0.001">
		<impulse algorithm="GS" atype="diagonal" maxiter="5"/>
	</engine>
	<default>
		<geom contype="0" condim="3" mindist="0.01" rgba=".8 .7 0 1" friction="1 .3 .3"/>
	</default>

	<world angle="degree">
		<geom type="plane" contype="1" pos="0 0 0"/>	

		<!-- Main torso section -->
		<body name="torso">
			<geom type="capsule" fromto="0 0 2 0 0 1.2" size="0.10"/>
			<geom type="capsule" fromto="0 -0.2 1.2 0 0.2 1.2" size="0.10"/>
			<geom type="capsule" fromto="0 -0.2 2 0 0.2 2" size="0.10"/>
			<geom type="sphere"  pos = "0 0 2.3" size="0.15"/>
			<!-- Torso DOF (uncomment last 3 for full freedom.)
			     Default is 3 DOF (for forward/backward).
			     -->
			<joint type="slide" pos="0 0 1.2" axis="1 0 0" limtype="1" limit="-5 10"/>
			<joint type="slide" pos="0 0 1.2" axis="0 0 1" limtype="1" limit="-5 10"/>
			<joint type="hinge" pos="0 0 1.2" axis="0 1 0" limtype="1" limit="-5 5"/>

			<!-- Extra DOFs
			<joint type="slide" pos="0 0 1.2" axis="0 1 0"/>
			<joint type="hinge" pos="0 0 1.2" axis="0 0 1"/>
			<joint type="hinge" pos="0 0 1.2" axis="1 0 0"/>
			-->
			
			<!-- Left Leg -->
			<body name="leftupper">
				<geom type="capsule" fromto="0 -0.2 1.2  0 -0.2 0.6" size="0.1"/>
				<joint type="hinge" limtype="1" limit="-90 60" pos="0 -0.2 1.2" axis="0 1 0"/>
				<body name="leftlower">
					<geom type="capsule" fromto="0 -0.2 0.6  0 -0.2 0.1  " size="0.08"/>
					<joint type="hinge" limtype="1" limit="-2 140" pos="0 -0.2 0.6" axis="0 1 0"/>
					<body name="leftfoot">
						<geom type="capsule" contype="1" fromto="0.2 -0.2 0.05  -0.1 -0.2 0.05  " size="0.05"/>
						<joint type="hinge" limtype="1" limit="-30 60" pos="0 -0.2 0.1" axis="0 1 0"/>
					</body>				
				</body>				
			</body>
			
			<!-- Right Leg -->
			<body name="rightupper">
				<geom type="capsule" fromto="0 0.2 1.2  0 0.2 0.6" size="0.1"/>
				<joint type="hinge" limtype="1" limit="-90 60" pos="0 0.2 1.2" axis="0 1 0"/>
				<body name="rightlower">
					<geom type="capsule" fromto="0 0.2 0.6  0 0.2 0.1  " size="0.08"/>
					<joint type="hinge" pos="0 0.2 0.6" limtype="1" limit="-2 140" axis="0 1 0"/>
					<body name="rightfoot">
						<geom type="capsule" fromto="0.2 0.2 0.05  -0.1 0.2 0.05  " size="0.05" contype="1"/>
						<joint type="hinge" pos="0 0.2 0.1" limtype="1" limit="-30 60" axis="0 1 0"/>
					</body>				
				</body>				
			</body>
			
			<!-- Left Hand -->
			<body name="upper">
				<geom name="upper" type="capsule" fromto="0 0.25 2.0 0 0.25 1.5" size=".08" />
				<joint name="upper" type="hinge" pos="0 0.25 2.0" axis="0 1 0" />
				<site name="start_upper" pos="0 0.25 2.0" />

				<body name="lower">
				  <geom name="lower" type="capsule" fromto="0 0.25 1.5 0.5 0.25 1.5" size=".065" />
				  <joint name="lower" type="hinge" pos="0 0.25 1.5" axis="0 1 0" />
				  <site name="end_lower" pos="0.5 0.25 1.5" />
				  
					<body name="finger1_1">
						<geom name="finger1_1" type="capsule" fromto="0.5 0.25 1.5   0.65 0.25 1.65" size=".02" rgba = "1 0.6 0.3 1" contype="1" />
						<joint name="finger1_1" limtype="1" limit="-90 90" type="hinge" pos="0.5 0.25 1.5" axis="0 1 0" />

						<body name="finger1_2">
						  <geom name="finger1_2" type="capsule" fromto="0.65 0.25 1.65    0.8 0.25 1.65" size=".015" rgba = "1 0.4 0.1 1" contype="1" />
						  <joint  name="finger1_2" limtype="1" limit="-45 135" type="hinge" pos="0.65 0.25 1.65" axis="0 1 0" />
						  <site name="end_finger1" pos="0.8 0.25 1.65" />
						</body>
						
					</body>

					<body name="finger2_1">
						<geom name="finger2_1" type="capsule" fromto = "0.5 0.25 1.5   0.65 0.25 1.35" size=".02" contype="1" />
						<joint name="finger2_1" limtype="1" limit="-90 90" type="hinge" pos="0.5 0.25 1.5" axis="0 1 0" />

						<body name="finger2_2">
						  <geom name="finger2_2" type="capsule" fromto="0.65 0.25 1.35 0.8 0.25 1.35" size=".015" contype="1" />
						  <joint name="finger2_2" limtype="1" limit="-135 45" type="hinge" pos="0.65 0.25 1.35" axis="0 1 0" />
						  <site name="end_finger2" pos="0.8 0.25 1.35" />
						</body>
					
					</body>
				</body>
			</body>
			
			<!-- Right Hand -->
			<body name="Rt_Arm">
				<geom type="capsule" fromto="0 -0.25 2.0 0 -0.25 1.5" size=".08" />
				<joint type="hinge" pos="0 0.25 2.0" axis="0 1 0" limtype="1" limit="-45 90"/>

				<body name="Rt_Forearm">
				  <geom type="capsule" fromto="0 -0.25 1.5 0.5 -0.25 1.5" size=".065" />
				  <joint type="hinge" pos="0 -0.25 1.5" axis="0 1 0" limtype="1" limit="-45 80" />
				</body>
			</body>
		</body>
		
		<body name="ball">
			<geom name="ball" type="sphere" pos="1.5 0.25 1.5" size=".1" contype="1" mass=".1" />
			<!-- use y-axis for 3 dimensional arm -->
			<!--<joint type="slide" pos="1.5 0 .1" axis="0 1 0" />-->
			<joint name="ball_x" type="slide" pos="1.5 0.25 .1" axis="1 0 0" limtype="1" limit="-100 100"/>
			<joint name="ball_z" type="slide" pos="1.5 0.25 .1" axis="0 0 1" limtype="1" limit="0 200"/>
      </body>
	</world>

</mujoco>